[2019-05-11 17:01:22,005: INFO/MainProcess] beat: Starting...
[2019-05-11 17:01:22,006: INFO/MainProcess] Writing entries...
[2019-05-11 17:01:27,382: INFO/MainProcess] Writing entries...
[2019-05-11 17:04:27,748: INFO/MainProcess] Writing entries...
[2019-05-11 17:07:28,114: INFO/MainProcess] Writing entries...
[2019-05-11 17:10:28,471: INFO/MainProcess] Writing entries...
[2019-05-11 17:13:28,833: INFO/MainProcess] Writing entries...
[2019-05-11 17:16:29,192: INFO/MainProcess] Writing entries...
[2019-05-11 17:19:29,555: INFO/MainProcess] Writing entries...
[2019-05-11 17:22:29,903: INFO/MainProcess] Writing entries...
[2019-05-11 17:25:30,246: INFO/MainProcess] Writing entries...
[2019-05-11 17:28:30,585: INFO/MainProcess] Writing entries...
[2019-05-11 17:31:30,948: INFO/MainProcess] Writing entries...
[2019-05-11 17:34:31,293: INFO/MainProcess] Writing entries...
[2019-05-11 17:37:31,648: INFO/MainProcess] Writing entries...
[2019-05-11 17:40:31,997: INFO/MainProcess] Writing entries...
[2019-05-11 17:43:32,336: INFO/MainProcess] Writing entries...
[2019-05-11 17:46:32,703: INFO/MainProcess] Writing entries...
[2019-05-11 17:49:33,352: INFO/MainProcess] Writing entries...
[2019-05-11 17:52:33,696: INFO/MainProcess] Writing entries...
[2019-05-11 17:55:34,054: INFO/MainProcess] Writing entries...
[2019-05-11 17:58:34,396: INFO/MainProcess] Writing entries...
[2019-05-11 18:01:34,746: INFO/MainProcess] Writing entries...
[2019-05-13 09:49:21,004: INFO/MainProcess] beat: Starting...
[2019-05-13 09:49:21,005: INFO/MainProcess] Writing entries...
[2019-05-13 09:49:21,417: ERROR/MainProcess] beat: Connection error: [Errno 111] Connection refused. Trying again in 2.0 seconds...
[2019-05-13 09:49:23,427: ERROR/MainProcess] beat: Connection error: [Errno 111] Connection refused. Trying again in 4.0 seconds...
[2019-05-13 09:49:27,439: ERROR/MainProcess] beat: Connection error: [Errno 111] Connection refused. Trying again in 6.0 seconds...
[2019-05-13 09:49:33,455: ERROR/MainProcess] beat: Connection error: [Errno 111] Connection refused. Trying again in 8.0 seconds...
[2019-05-13 09:49:41,472: ERROR/MainProcess] beat: Connection error: [Errno 111] Connection refused. Trying again in 10.0 seconds...
[2019-05-13 09:49:51,494: ERROR/MainProcess] beat: Connection error: [Errno 111] Connection refused. Trying again in 12.0 seconds...
[2019-05-13 09:50:03,515: ERROR/MainProcess] beat: Connection error: [Errno 111] Connection refused. Trying again in 14.0 seconds...
[2019-05-13 09:50:17,539: ERROR/MainProcess] beat: Connection error: [Errno 111] Connection refused. Trying again in 16.0 seconds...
[2019-05-13 09:50:33,564: ERROR/MainProcess] beat: Connection error: [Errno 111] Connection refused. Trying again in 18.0 seconds...
[2019-05-13 09:50:51,593: ERROR/MainProcess] beat: Connection error: [Errno 111] Connection refused. Trying again in 20.0 seconds...
[2019-05-13 09:51:11,626: ERROR/MainProcess] beat: Connection error: [Errno 111] Connection refused. Trying again in 22.0 seconds...
[2019-05-13 09:51:33,658: ERROR/MainProcess] beat: Connection error: [Errno 111] Connection refused. Trying again in 24.0 seconds...
[2019-05-13 09:51:57,690: ERROR/MainProcess] beat: Connection error: [Errno 111] Connection refused. Trying again in 26.0 seconds...
[2019-05-13 09:52:23,727: ERROR/MainProcess] beat: Connection error: [Errno 111] Connection refused. Trying again in 28.0 seconds...
[2019-05-13 09:52:51,765: ERROR/MainProcess] beat: Connection error: [Errno 111] Connection refused. Trying again in 30.0 seconds...
[2019-05-13 09:53:21,805: ERROR/MainProcess] beat: Connection error: [Errno 111] Connection refused. Trying again in 32.0 seconds...
[2019-05-13 09:53:53,848: ERROR/MainProcess] beat: Connection error: [Errno 111] Connection refused. Trying again in 32.0 seconds...
[2019-05-13 09:54:25,890: ERROR/MainProcess] beat: Connection error: [Errno 111] Connection refused. Trying again in 32.0 seconds...
[2019-05-13 09:54:57,932: ERROR/MainProcess] beat: Connection error: [Errno 111] Connection refused. Trying again in 32.0 seconds...
[2019-05-13 09:55:29,974: ERROR/MainProcess] beat: Connection error: [Errno 111] Connection refused. Trying again in 32.0 seconds...
[2019-05-13 09:56:02,015: ERROR/MainProcess] beat: Connection error: [Errno 111] Connection refused. Trying again in 32.0 seconds...
[2019-05-13 09:56:34,057: ERROR/MainProcess] beat: Connection error: [Errno 111] Connection refused. Trying again in 32.0 seconds...
[2019-05-13 09:57:06,097: ERROR/MainProcess] beat: Connection error: [Errno 111] Connection refused. Trying again in 32.0 seconds...
[2019-05-13 09:57:38,139: ERROR/MainProcess] beat: Connection error: [Errno 111] Connection refused. Trying again in 32.0 seconds...
[2019-05-13 09:58:10,181: ERROR/MainProcess] beat: Connection error: [Errno 111] Connection refused. Trying again in 32.0 seconds...
[2019-05-13 09:58:42,223: ERROR/MainProcess] beat: Connection error: [Errno 111] Connection refused. Trying again in 32.0 seconds...
[2019-05-13 09:59:14,266: ERROR/MainProcess] beat: Connection error: [Errno 111] Connection refused. Trying again in 32.0 seconds...
[2019-05-13 09:59:46,307: ERROR/MainProcess] beat: Connection error: [Errno 111] Connection refused. Trying again in 32.0 seconds...
[2019-05-13 10:00:18,349: ERROR/MainProcess] beat: Connection error: [Errno 111] Connection refused. Trying again in 32.0 seconds...
[2019-05-13 10:00:50,390: ERROR/MainProcess] beat: Connection error: [Errno 111] Connection refused. Trying again in 32.0 seconds...
[2019-05-13 10:01:22,432: ERROR/MainProcess] beat: Connection error: [Errno 111] Connection refused. Trying again in 32.0 seconds...
[2019-05-13 10:01:54,474: ERROR/MainProcess] beat: Connection error: [Errno 111] Connection refused. Trying again in 32.0 seconds...
[2019-05-13 10:02:26,516: ERROR/MainProcess] beat: Connection error: [Errno 111] Connection refused. Trying again in 32.0 seconds...
[2019-05-13 10:02:58,557: ERROR/MainProcess] beat: Connection error: [Errno 111] Connection refused. Trying again in 32.0 seconds...
[2019-05-13 10:03:30,599: ERROR/MainProcess] beat: Connection error: [Errno 111] Connection refused. Trying again in 32.0 seconds...
[2019-05-13 10:04:02,640: ERROR/MainProcess] beat: Connection error: [Errno 111] Connection refused. Trying again in 32.0 seconds...
[2019-05-13 10:04:34,682: ERROR/MainProcess] beat: Connection error: [Errno 111] Connection refused. Trying again in 32.0 seconds...
[2019-05-13 10:05:06,724: ERROR/MainProcess] beat: Connection error: [Errno 111] Connection refused. Trying again in 32.0 seconds...
[2019-05-13 10:05:38,766: ERROR/MainProcess] beat: Connection error: [Errno 111] Connection refused. Trying again in 32.0 seconds...
[2019-05-13 10:06:10,808: ERROR/MainProcess] beat: Connection error: [Errno 111] Connection refused. Trying again in 32.0 seconds...
[2019-05-13 10:06:42,851: ERROR/MainProcess] beat: Connection error: [Errno 111] Connection refused. Trying again in 32.0 seconds...
[2019-05-13 10:07:14,893: ERROR/MainProcess] beat: Connection error: [Errno 111] Connection refused. Trying again in 32.0 seconds...
[2019-05-13 10:07:46,934: ERROR/MainProcess] beat: Connection error: [Errno 111] Connection refused. Trying again in 32.0 seconds...
[2019-05-13 10:08:18,978: ERROR/MainProcess] beat: Connection error: [Errno 111] Connection refused. Trying again in 32.0 seconds...
[2019-05-13 10:08:51,020: ERROR/MainProcess] beat: Connection error: [Errno 111] Connection refused. Trying again in 32.0 seconds...
[2019-05-13 10:09:23,060: ERROR/MainProcess] beat: Connection error: [Errno 111] Connection refused. Trying again in 32.0 seconds...
[2019-05-13 10:09:55,102: ERROR/MainProcess] beat: Connection error: [Errno 111] Connection refused. Trying again in 32.0 seconds...
[2019-05-13 10:10:27,143: ERROR/MainProcess] beat: Connection error: [Errno 111] Connection refused. Trying again in 32.0 seconds...
[2019-05-13 10:10:59,186: ERROR/MainProcess] beat: Connection error: [Errno 111] Connection refused. Trying again in 32.0 seconds...
[2019-05-13 10:11:31,231: ERROR/MainProcess] beat: Connection error: [Errno 111] Connection refused. Trying again in 32.0 seconds...
[2019-05-13 10:12:03,274: ERROR/MainProcess] beat: Connection error: [Errno 111] Connection refused. Trying again in 32.0 seconds...
[2019-05-13 10:12:35,318: ERROR/MainProcess] beat: Connection error: [Errno 111] Connection refused. Trying again in 32.0 seconds...
[2019-05-13 10:13:07,360: ERROR/MainProcess] beat: Connection error: [Errno 111] Connection refused. Trying again in 32.0 seconds...
[2019-05-13 10:13:39,403: ERROR/MainProcess] beat: Connection error: [Errno 111] Connection refused. Trying again in 32.0 seconds...
[2019-05-13 10:14:11,444: ERROR/MainProcess] beat: Connection error: [Errno 111] Connection refused. Trying again in 32.0 seconds...
[2019-05-13 10:14:43,485: ERROR/MainProcess] beat: Connection error: [Errno 111] Connection refused. Trying again in 32.0 seconds...
[2019-05-13 10:15:15,527: ERROR/MainProcess] beat: Connection error: [Errno 111] Connection refused. Trying again in 32.0 seconds...
[2019-05-13 10:15:47,567: ERROR/MainProcess] beat: Connection error: [Errno 111] Connection refused. Trying again in 32.0 seconds...
[2019-05-13 10:16:19,610: ERROR/MainProcess] beat: Connection error: [Errno 111] Connection refused. Trying again in 32.0 seconds...
[2019-05-13 10:16:51,651: ERROR/MainProcess] beat: Connection error: [Errno 111] Connection refused. Trying again in 32.0 seconds...
[2019-05-13 10:17:23,695: ERROR/MainProcess] beat: Connection error: [Errno 111] Connection refused. Trying again in 32.0 seconds...
[2019-05-13 10:17:55,741: ERROR/MainProcess] beat: Connection error: [Errno 111] Connection refused. Trying again in 32.0 seconds...
[2019-05-13 10:18:27,783: ERROR/MainProcess] beat: Connection error: [Errno 111] Connection refused. Trying again in 32.0 seconds...
[2019-05-13 10:18:59,825: ERROR/MainProcess] beat: Connection error: [Errno 111] Connection refused. Trying again in 32.0 seconds...
[2019-05-13 10:19:31,868: ERROR/MainProcess] beat: Connection error: [Errno 111] Connection refused. Trying again in 32.0 seconds...
[2019-05-13 10:20:03,909: ERROR/MainProcess] beat: Connection error: [Errno 111] Connection refused. Trying again in 32.0 seconds...
[2019-05-13 10:20:35,951: ERROR/MainProcess] beat: Connection error: [Errno 111] Connection refused. Trying again in 32.0 seconds...
[2019-05-13 10:21:07,992: ERROR/MainProcess] beat: Connection error: [Errno 111] Connection refused. Trying again in 32.0 seconds...
[2019-05-13 10:21:40,035: ERROR/MainProcess] beat: Connection error: [Errno 111] Connection refused. Trying again in 32.0 seconds...
[2019-05-13 10:22:12,075: ERROR/MainProcess] beat: Connection error: [Errno 111] Connection refused. Trying again in 32.0 seconds...
[2019-05-13 10:22:44,118: ERROR/MainProcess] beat: Connection error: [Errno 111] Connection refused. Trying again in 32.0 seconds...
[2019-05-13 10:23:16,159: ERROR/MainProcess] beat: Connection error: [Errno 111] Connection refused. Trying again in 32.0 seconds...
[2019-05-13 10:23:48,200: ERROR/MainProcess] beat: Connection error: [Errno 111] Connection refused. Trying again in 32.0 seconds...
[2019-05-13 10:24:20,241: ERROR/MainProcess] beat: Connection error: [Errno 111] Connection refused. Trying again in 32.0 seconds...
[2019-05-13 10:24:52,283: ERROR/MainProcess] beat: Connection error: [Errno 111] Connection refused. Trying again in 32.0 seconds...
[2019-05-13 10:25:24,325: ERROR/MainProcess] beat: Connection error: [Errno 111] Connection refused. Trying again in 32.0 seconds...
[2019-05-13 10:25:56,368: ERROR/MainProcess] beat: Connection error: [Errno 111] Connection refused. Trying again in 32.0 seconds...
[2019-05-13 10:26:28,410: ERROR/MainProcess] beat: Connection error: [Errno 111] Connection refused. Trying again in 32.0 seconds...
[2019-05-13 10:27:00,451: ERROR/MainProcess] beat: Connection error: [Errno 111] Connection refused. Trying again in 32.0 seconds...
[2019-05-13 10:27:32,495: ERROR/MainProcess] beat: Connection error: [Errno 111] Connection refused. Trying again in 32.0 seconds...
[2019-05-13 10:28:04,537: ERROR/MainProcess] beat: Connection error: [Errno 111] Connection refused. Trying again in 32.0 seconds...
[2019-05-13 10:28:36,579: ERROR/MainProcess] beat: Connection error: [Errno 111] Connection refused. Trying again in 32.0 seconds...
[2019-05-13 10:29:08,627: ERROR/MainProcess] beat: Connection error: [Errno 111] Connection refused. Trying again in 32.0 seconds...
[2019-05-13 10:29:40,667: ERROR/MainProcess] beat: Connection error: [Errno 111] Connection refused. Trying again in 32.0 seconds...
[2019-05-13 10:30:12,720: ERROR/MainProcess] beat: Connection error: [Errno 111] Connection refused. Trying again in 32.0 seconds...
[2019-05-13 10:30:44,761: ERROR/MainProcess] beat: Connection error: [Errno 111] Connection refused. Trying again in 32.0 seconds...
[2019-05-13 10:31:16,804: ERROR/MainProcess] beat: Connection error: [Errno 111] Connection refused. Trying again in 32.0 seconds...
[2019-05-13 10:31:48,844: ERROR/MainProcess] beat: Connection error: [Errno 111] Connection refused. Trying again in 32.0 seconds...
[2019-05-13 10:32:20,885: ERROR/MainProcess] beat: Connection error: [Errno 111] Connection refused. Trying again in 32.0 seconds...
[2019-05-13 10:32:52,928: ERROR/MainProcess] beat: Connection error: [Errno 111] Connection refused. Trying again in 32.0 seconds...
[2019-05-13 10:33:24,971: ERROR/MainProcess] beat: Connection error: [Errno 111] Connection refused. Trying again in 32.0 seconds...
[2019-05-13 10:33:57,012: ERROR/MainProcess] beat: Connection error: [Errno 111] Connection refused. Trying again in 32.0 seconds...
[2019-05-13 10:34:29,053: ERROR/MainProcess] beat: Connection error: [Errno 111] Connection refused. Trying again in 32.0 seconds...
[2019-05-13 10:35:01,095: ERROR/MainProcess] beat: Connection error: [Errno 111] Connection refused. Trying again in 32.0 seconds...
[2019-05-13 10:35:33,137: ERROR/MainProcess] beat: Connection error: [Errno 111] Connection refused. Trying again in 32.0 seconds...
[2019-05-13 10:36:05,188: ERROR/MainProcess] beat: Connection error: [Errno 111] Connection refused. Trying again in 32.0 seconds...
[2019-05-13 10:36:37,230: ERROR/MainProcess] beat: Connection error: [Errno 111] Connection refused. Trying again in 32.0 seconds...
[2019-05-13 10:37:09,273: ERROR/MainProcess] beat: Connection error: [Errno 111] Connection refused. Trying again in 32.0 seconds...
[2019-05-13 10:37:41,315: ERROR/MainProcess] beat: Connection error: [Errno 111] Connection refused. Trying again in 32.0 seconds...
[2019-05-13 10:38:13,357: ERROR/MainProcess] beat: Connection error: [Errno 111] Connection refused. Trying again in 32.0 seconds...
[2019-05-13 10:38:45,399: INFO/MainProcess] Writing entries...
[2019-05-13 10:38:45,409: WARNING/MainProcess] /home/renyongxiang/.local/lib/python3.4/site-packages/django/db/models/fields/__init__.py:1423: RuntimeWarning: DateTimeField PeriodicTask.last_run_at received a naive datetime (2019-05-13 10:38:45.407353) while time zone support is active.
  RuntimeWarning)
[2019-05-13 10:38:45,498: CRITICAL/MainProcess] beat raised exception <class 'kombu.exceptions.OperationalError'>: OperationalError('[Errno 111] Connection refused',)
Traceback (most recent call last):
  File "/home/renyongxiang/.local/lib/python3.4/site-packages/kombu/utils/objects.py", line 42, in __get__
    return obj.__dict__[self.__name__]
KeyError: 'producer'

During handling of the above exception, another exception occurred:

Traceback (most recent call last):
  File "/home/renyongxiang/.local/lib/python3.4/site-packages/amqp/transport.py", line 141, in _connect
    host, port, family, socket.SOCK_STREAM, SOL_TCP)
  File "/usr/lib/python3.4/socket.py", line 533, in getaddrinfo
    for res in _socket.getaddrinfo(host, port, family, type, proto, flags):
socket.gaierror: [Errno -9] Address family for hostname not supported

During handling of the above exception, another exception occurred:

Traceback (most recent call last):
  File "/home/renyongxiang/.local/lib/python3.4/site-packages/kombu/connection.py", line 431, in _reraise_as_library_errors
    yield
  File "/home/renyongxiang/.local/lib/python3.4/site-packages/kombu/connection.py", line 422, in ensure_connection
    callback, timeout=timeout)
  File "/home/renyongxiang/.local/lib/python3.4/site-packages/kombu/utils/functional.py", line 341, in retry_over_time
    return fun(*args, **kwargs)
  File "/home/renyongxiang/.local/lib/python3.4/site-packages/kombu/connection.py", line 275, in connect
    return self.connection
  File "/home/renyongxiang/.local/lib/python3.4/site-packages/kombu/connection.py", line 823, in connection
    self._connection = self._establish_connection()
  File "/home/renyongxiang/.local/lib/python3.4/site-packages/kombu/connection.py", line 778, in _establish_connection
    conn = self.transport.establish_connection()
  File "/home/renyongxiang/.local/lib/python3.4/site-packages/kombu/transport/pyamqp.py", line 130, in establish_connection
    conn.connect()
  File "/home/renyongxiang/.local/lib/python3.4/site-packages/amqp/connection.py", line 307, in connect
    self.transport.connect()
  File "/home/renyongxiang/.local/lib/python3.4/site-packages/amqp/transport.py", line 81, in connect
    self._connect(self.host, self.port, self.connect_timeout)
  File "/home/renyongxiang/.local/lib/python3.4/site-packages/amqp/transport.py", line 152, in _connect
    "failed to resolve broker hostname"))
  File "/home/renyongxiang/.local/lib/python3.4/site-packages/amqp/transport.py", line 165, in _connect
    self.sock.connect(sa)
ConnectionRefusedError: [Errno 111] Connection refused

During handling of the above exception, another exception occurred:

Traceback (most recent call last):
  File "/home/renyongxiang/.local/lib/python3.4/site-packages/celery/apps/beat.py", line 109, in start_scheduler
    service.start()
  File "/home/renyongxiang/.local/lib/python3.4/site-packages/celery/beat.py", line 597, in start
    interval = self.scheduler.tick()
  File "/home/renyongxiang/.local/lib/python3.4/site-packages/celery/beat.py", line 312, in tick
    self.apply_entry(entry, producer=self.producer)
  File "/home/renyongxiang/.local/lib/python3.4/site-packages/kombu/utils/objects.py", line 44, in __get__
    value = obj.__dict__[self.__name__] = self.__get(obj)
  File "/home/renyongxiang/.local/lib/python3.4/site-packages/celery/beat.py", line 450, in producer
    return self.Producer(self._ensure_connected(), auto_declare=False)
  File "/home/renyongxiang/.local/lib/python3.4/site-packages/celery/beat.py", line 434, in _ensure_connected
    _error_handler, self.app.conf.broker_connection_max_retries
  File "/home/renyongxiang/.local/lib/python3.4/site-packages/kombu/connection.py", line 422, in ensure_connection
    callback, timeout=timeout)
  File "/usr/lib/python3.4/contextlib.py", line 77, in __exit__
    self.gen.throw(type, value, traceback)
  File "/home/renyongxiang/.local/lib/python3.4/site-packages/kombu/connection.py", line 436, in _reraise_as_library_errors
    sys.exc_info()[2])
  File "/home/renyongxiang/.local/lib/python3.4/site-packages/vine/five.py", line 194, in reraise
    raise value.with_traceback(tb)
  File "/home/renyongxiang/.local/lib/python3.4/site-packages/kombu/connection.py", line 431, in _reraise_as_library_errors
    yield
  File "/home/renyongxiang/.local/lib/python3.4/site-packages/kombu/connection.py", line 422, in ensure_connection
    callback, timeout=timeout)
  File "/home/renyongxiang/.local/lib/python3.4/site-packages/kombu/utils/functional.py", line 341, in retry_over_time
    return fun(*args, **kwargs)
  File "/home/renyongxiang/.local/lib/python3.4/site-packages/kombu/connection.py", line 275, in connect
    return self.connection
  File "/home/renyongxiang/.local/lib/python3.4/site-packages/kombu/connection.py", line 823, in connection
    self._connection = self._establish_connection()
  File "/home/renyongxiang/.local/lib/python3.4/site-packages/kombu/connection.py", line 778, in _establish_connection
    conn = self.transport.establish_connection()
  File "/home/renyongxiang/.local/lib/python3.4/site-packages/kombu/transport/pyamqp.py", line 130, in establish_connection
    conn.connect()
  File "/home/renyongxiang/.local/lib/python3.4/site-packages/amqp/connection.py", line 307, in connect
    self.transport.connect()
  File "/home/renyongxiang/.local/lib/python3.4/site-packages/amqp/transport.py", line 81, in connect
    self._connect(self.host, self.port, self.connect_timeout)
  File "/home/renyongxiang/.local/lib/python3.4/site-packages/amqp/transport.py", line 152, in _connect
    "failed to resolve broker hostname"))
  File "/home/renyongxiang/.local/lib/python3.4/site-packages/amqp/transport.py", line 165, in _connect
    self.sock.connect(sa)
kombu.exceptions.OperationalError: [Errno 111] Connection refused
[2019-05-13 10:38:45,608: WARNING/MainProcess] Traceback (most recent call last):
[2019-05-13 10:38:45,609: WARNING/MainProcess] File "/home/renyongxiang/.local/lib/python3.4/site-packages/kombu/utils/objects.py", line 42, in __get__
[2019-05-13 10:38:45,609: WARNING/MainProcess] return obj.__dict__[self.__name__]
[2019-05-13 10:38:45,609: WARNING/MainProcess] KeyError
[2019-05-13 10:38:45,609: WARNING/MainProcess] :
[2019-05-13 10:38:45,609: WARNING/MainProcess] 'producer'
[2019-05-13 10:38:45,609: WARNING/MainProcess] During handling of the above exception, another exception occurred:
[2019-05-13 10:38:45,609: WARNING/MainProcess] Traceback (most recent call last):
[2019-05-13 10:38:45,610: WARNING/MainProcess] File "/home/renyongxiang/.local/lib/python3.4/site-packages/amqp/transport.py", line 141, in _connect
[2019-05-13 10:38:45,610: WARNING/MainProcess] host, port, family, socket.SOCK_STREAM, SOL_TCP)
[2019-05-13 10:38:45,610: WARNING/MainProcess] File "/usr/lib/python3.4/socket.py", line 533, in getaddrinfo
[2019-05-13 10:38:45,610: WARNING/MainProcess] for res in _socket.getaddrinfo(host, port, family, type, proto, flags):
[2019-05-13 10:38:45,610: WARNING/MainProcess] socket
[2019-05-13 10:38:45,610: WARNING/MainProcess] .
[2019-05-13 10:38:45,611: WARNING/MainProcess] gaierror
[2019-05-13 10:38:45,611: WARNING/MainProcess] :
[2019-05-13 10:38:45,611: WARNING/MainProcess] [Errno -9] Address family for hostname not supported
[2019-05-13 10:38:45,611: WARNING/MainProcess] During handling of the above exception, another exception occurred:
[2019-05-13 10:38:45,611: WARNING/MainProcess] Traceback (most recent call last):
[2019-05-13 10:38:45,611: WARNING/MainProcess] File "/home/renyongxiang/.local/lib/python3.4/site-packages/kombu/connection.py", line 431, in _reraise_as_library_errors
[2019-05-13 10:38:45,611: WARNING/MainProcess] yield
[2019-05-13 10:38:45,611: WARNING/MainProcess] File "/home/renyongxiang/.local/lib/python3.4/site-packages/kombu/connection.py", line 422, in ensure_connection
[2019-05-13 10:38:45,612: WARNING/MainProcess] callback, timeout=timeout)
[2019-05-13 10:38:45,612: WARNING/MainProcess] File "/home/renyongxiang/.local/lib/python3.4/site-packages/kombu/utils/functional.py", line 341, in retry_over_time
[2019-05-13 10:38:45,612: WARNING/MainProcess] return fun(*args, **kwargs)
[2019-05-13 10:38:45,612: WARNING/MainProcess] File "/home/renyongxiang/.local/lib/python3.4/site-packages/kombu/connection.py", line 275, in connect
[2019-05-13 10:38:45,612: WARNING/MainProcess] return self.connection
[2019-05-13 10:38:45,613: WARNING/MainProcess] File "/home/renyongxiang/.local/lib/python3.4/site-packages/kombu/connection.py", line 823, in connection
[2019-05-13 10:38:45,613: WARNING/MainProcess] self._connection = self._establish_connection()
[2019-05-13 10:38:45,613: WARNING/MainProcess] File "/home/renyongxiang/.local/lib/python3.4/site-packages/kombu/connection.py", line 778, in _establish_connection
[2019-05-13 10:38:45,613: WARNING/MainProcess] conn = self.transport.establish_connection()
[2019-05-13 10:38:45,614: WARNING/MainProcess] File "/home/renyongxiang/.local/lib/python3.4/site-packages/kombu/transport/pyamqp.py", line 130, in establish_connection
[2019-05-13 10:38:45,614: WARNING/MainProcess] conn.connect()
[2019-05-13 10:38:45,614: WARNING/MainProcess] File "/home/renyongxiang/.local/lib/python3.4/site-packages/amqp/connection.py", line 307, in connect
[2019-05-13 10:38:45,614: WARNING/MainProcess] self.transport.connect()
[2019-05-13 10:38:45,614: WARNING/MainProcess] File "/home/renyongxiang/.local/lib/python3.4/site-packages/amqp/transport.py", line 81, in connect
[2019-05-13 10:38:45,614: WARNING/MainProcess] self._connect(self.host, self.port, self.connect_timeout)
[2019-05-13 10:38:45,615: WARNING/MainProcess] File "/home/renyongxiang/.local/lib/python3.4/site-packages/amqp/transport.py", line 152, in _connect
[2019-05-13 10:38:45,615: WARNING/MainProcess] "failed to resolve broker hostname"))
[2019-05-13 10:38:45,615: WARNING/MainProcess] File "/home/renyongxiang/.local/lib/python3.4/site-packages/amqp/transport.py", line 165, in _connect
[2019-05-13 10:38:45,615: WARNING/MainProcess] self.sock.connect(sa)
[2019-05-13 10:38:45,615: WARNING/MainProcess] ConnectionRefusedError
[2019-05-13 10:38:45,615: WARNING/MainProcess] :
[2019-05-13 10:38:45,615: WARNING/MainProcess] [Errno 111] Connection refused
[2019-05-13 10:38:45,616: WARNING/MainProcess] During handling of the above exception, another exception occurred:
[2019-05-13 10:38:45,616: WARNING/MainProcess] Traceback (most recent call last):
[2019-05-13 10:38:45,616: WARNING/MainProcess] File "/home/renyongxiang/.local/bin/celery", line 10, in <module>
[2019-05-13 10:38:45,616: WARNING/MainProcess] sys.exit(main())
[2019-05-13 10:38:45,616: WARNING/MainProcess] File "/home/renyongxiang/.local/lib/python3.4/site-packages/celery/__main__.py", line 16, in main
[2019-05-13 10:38:45,616: WARNING/MainProcess] _main()
[2019-05-13 10:38:45,616: WARNING/MainProcess] File "/home/renyongxiang/.local/lib/python3.4/site-packages/celery/bin/celery.py", line 322, in main
[2019-05-13 10:38:45,634: WARNING/MainProcess] cmd.execute_from_commandline(argv)
[2019-05-13 10:38:45,634: WARNING/MainProcess] File "/home/renyongxiang/.local/lib/python3.4/site-packages/celery/bin/celery.py", line 496, in execute_from_commandline
[2019-05-13 10:38:45,635: WARNING/MainProcess] super(CeleryCommand, self).execute_from_commandline(argv)))
[2019-05-13 10:38:45,635: WARNING/MainProcess] File "/home/renyongxiang/.local/lib/python3.4/site-packages/celery/bin/base.py", line 298, in execute_from_commandline
[2019-05-13 10:38:45,640: WARNING/MainProcess] return self.handle_argv(self.prog_name, argv[1:])
[2019-05-13 10:38:45,640: WARNING/MainProcess] File "/home/renyongxiang/.local/lib/python3.4/site-packages/celery/bin/celery.py", line 488, in handle_argv
[2019-05-13 10:38:45,641: WARNING/MainProcess] return self.execute(command, argv)
[2019-05-13 10:38:45,641: WARNING/MainProcess] File "/home/renyongxiang/.local/lib/python3.4/site-packages/celery/bin/celery.py", line 420, in execute
[2019-05-13 10:38:45,641: WARNING/MainProcess] ).run_from_argv(self.prog_name, argv[1:], command=argv[0])
[2019-05-13 10:38:45,641: WARNING/MainProcess] File "/home/renyongxiang/.local/lib/python3.4/site-packages/celery/bin/base.py", line 302, in run_from_argv
[2019-05-13 10:38:45,642: WARNING/MainProcess] sys.argv if argv is None else argv, command)
[2019-05-13 10:38:45,642: WARNING/MainProcess] File "/home/renyongxiang/.local/lib/python3.4/site-packages/celery/bin/base.py", line 386, in handle_argv
[2019-05-13 10:38:45,642: WARNING/MainProcess] return self(*args, **options)
[2019-05-13 10:38:45,642: WARNING/MainProcess] File "/home/renyongxiang/.local/lib/python3.4/site-packages/celery/bin/base.py", line 252, in __call__
[2019-05-13 10:38:45,642: WARNING/MainProcess] ret = self.run(*args, **kwargs)
[2019-05-13 10:38:45,642: WARNING/MainProcess] File "/home/renyongxiang/.local/lib/python3.4/site-packages/celery/bin/beat.py", line 109, in run
[2019-05-13 10:38:45,647: WARNING/MainProcess] return beat().run()
[2019-05-13 10:38:45,647: WARNING/MainProcess] File "/home/renyongxiang/.local/lib/python3.4/site-packages/celery/apps/beat.py", line 81, in run
[2019-05-13 10:38:45,647: WARNING/MainProcess] self.start_scheduler()
[2019-05-13 10:38:45,647: WARNING/MainProcess] File "/home/renyongxiang/.local/lib/python3.4/site-packages/celery/apps/beat.py", line 109, in start_scheduler
[2019-05-13 10:38:45,647: WARNING/MainProcess] service.start()
[2019-05-13 10:38:45,648: WARNING/MainProcess] File "/home/renyongxiang/.local/lib/python3.4/site-packages/celery/beat.py", line 597, in start
[2019-05-13 10:38:45,648: WARNING/MainProcess] interval = self.scheduler.tick()
[2019-05-13 10:38:45,648: WARNING/MainProcess] File "/home/renyongxiang/.local/lib/python3.4/site-packages/celery/beat.py", line 312, in tick
[2019-05-13 10:38:45,648: WARNING/MainProcess] self.apply_entry(entry, producer=self.producer)
[2019-05-13 10:38:45,648: WARNING/MainProcess] File "/home/renyongxiang/.local/lib/python3.4/site-packages/kombu/utils/objects.py", line 44, in __get__
[2019-05-13 10:38:45,649: WARNING/MainProcess] value = obj.__dict__[self.__name__] = self.__get(obj)
[2019-05-13 10:38:45,649: WARNING/MainProcess] File "/home/renyongxiang/.local/lib/python3.4/site-packages/celery/beat.py", line 450, in producer
[2019-05-13 10:38:45,649: WARNING/MainProcess] return self.Producer(self._ensure_connected(), auto_declare=False)
[2019-05-13 10:38:45,649: WARNING/MainProcess] File "/home/renyongxiang/.local/lib/python3.4/site-packages/celery/beat.py", line 434, in _ensure_connected
[2019-05-13 10:38:45,649: WARNING/MainProcess] _error_handler, self.app.conf.broker_connection_max_retries
[2019-05-13 10:38:45,650: WARNING/MainProcess] File "/home/renyongxiang/.local/lib/python3.4/site-packages/kombu/connection.py", line 422, in ensure_connection
[2019-05-13 10:38:45,650: WARNING/MainProcess] callback, timeout=timeout)
[2019-05-13 10:38:45,650: WARNING/MainProcess] File "/usr/lib/python3.4/contextlib.py", line 77, in __exit__
[2019-05-13 10:38:45,650: WARNING/MainProcess] self.gen.throw(type, value, traceback)
[2019-05-13 10:38:45,650: WARNING/MainProcess] File "/home/renyongxiang/.local/lib/python3.4/site-packages/kombu/connection.py", line 436, in _reraise_as_library_errors
[2019-05-13 10:38:45,651: WARNING/MainProcess] sys.exc_info()[2])
[2019-05-13 10:38:45,651: WARNING/MainProcess] File "/home/renyongxiang/.local/lib/python3.4/site-packages/vine/five.py", line 194, in reraise
[2019-05-13 10:38:45,651: WARNING/MainProcess] raise value.with_traceback(tb)
[2019-05-13 10:38:45,651: WARNING/MainProcess] File "/home/renyongxiang/.local/lib/python3.4/site-packages/kombu/connection.py", line 431, in _reraise_as_library_errors
[2019-05-13 10:38:45,651: WARNING/MainProcess] yield
[2019-05-13 10:38:45,651: WARNING/MainProcess] File "/home/renyongxiang/.local/lib/python3.4/site-packages/kombu/connection.py", line 422, in ensure_connection
[2019-05-13 10:38:45,652: WARNING/MainProcess] callback, timeout=timeout)
[2019-05-13 10:38:45,652: WARNING/MainProcess] File "/home/renyongxiang/.local/lib/python3.4/site-packages/kombu/utils/functional.py", line 341, in retry_over_time
[2019-05-13 10:38:45,652: WARNING/MainProcess] return fun(*args, **kwargs)
[2019-05-13 10:38:45,652: WARNING/MainProcess] File "/home/renyongxiang/.local/lib/python3.4/site-packages/kombu/connection.py", line 275, in connect
[2019-05-13 10:38:45,652: WARNING/MainProcess] return self.connection
[2019-05-13 10:38:45,653: WARNING/MainProcess] File "/home/renyongxiang/.local/lib/python3.4/site-packages/kombu/connection.py", line 823, in connection
[2019-05-13 10:38:45,653: WARNING/MainProcess] self._connection = self._establish_connection()
[2019-05-13 10:38:45,653: WARNING/MainProcess] File "/home/renyongxiang/.local/lib/python3.4/site-packages/kombu/connection.py", line 778, in _establish_connection
[2019-05-13 10:38:45,653: WARNING/MainProcess] conn = self.transport.establish_connection()
[2019-05-13 10:38:45,653: WARNING/MainProcess] File "/home/renyongxiang/.local/lib/python3.4/site-packages/kombu/transport/pyamqp.py", line 130, in establish_connection
[2019-05-13 10:38:45,654: WARNING/MainProcess] conn.connect()
[2019-05-13 10:38:45,654: WARNING/MainProcess] File "/home/renyongxiang/.local/lib/python3.4/site-packages/amqp/connection.py", line 307, in connect
[2019-05-13 10:38:45,654: WARNING/MainProcess] self.transport.connect()
[2019-05-13 10:38:45,654: WARNING/MainProcess] File "/home/renyongxiang/.local/lib/python3.4/site-packages/amqp/transport.py", line 81, in connect
[2019-05-13 10:38:45,654: WARNING/MainProcess] self._connect(self.host, self.port, self.connect_timeout)
[2019-05-13 10:38:45,654: WARNING/MainProcess] File "/home/renyongxiang/.local/lib/python3.4/site-packages/amqp/transport.py", line 152, in _connect
[2019-05-13 10:38:45,655: WARNING/MainProcess] "failed to resolve broker hostname"))
[2019-05-13 10:38:45,655: WARNING/MainProcess] File "/home/renyongxiang/.local/lib/python3.4/site-packages/amqp/transport.py", line 165, in _connect
[2019-05-13 10:38:45,655: WARNING/MainProcess] self.sock.connect(sa)
[2019-05-13 10:38:45,655: WARNING/MainProcess] kombu.exceptions
[2019-05-13 10:38:45,655: WARNING/MainProcess] .
[2019-05-13 10:38:45,655: WARNING/MainProcess] OperationalError
[2019-05-13 10:38:45,655: WARNING/MainProcess] :
[2019-05-13 10:38:45,656: WARNING/MainProcess] [Errno 111] Connection refused
[2019-05-13 10:38:45,656: INFO/MainProcess] Writing entries...
[2019-05-13 10:38:45,656: INFO/MainProcess] Writing entries...
